// During handle process of exception, there should not have another exception again, or std library function terminate is called to terminate the program processing.
